Workbook
Name PRODUTO: Planilha1!$A$3:$A$6924
Name PRODUTOADEGA: 'BASE DE DADOS'!$A$4:$A$1875

Sheet Planilha1
A1: Produto | B1: Código Produto | C1: Código Acesso | D1: Preço Vda Unitário | E1: Preço Marg.Zero | F1: Lucrat. Marg % | G1: Custo Liq. Unitário | H1: Média Vda/Dia
A2: TOTAL: 6922 linhas | D2: 9.55 | E2: 12.58 | F2: 27.53 | G2: 6.2201 | H2: 76247.513
A3: ABACAXI CALDA OLE 400G | B3: 6157 | C3: 7891032016601 | D3: 19.9 | E3: 15.28 | F3: 0.2107 | G3: 13.8659 | H3: 1.9
A4: ABOBORA CALDA SEGREDOS FAZENDA 200G | B4: 67914 | C4: 7896659120557 | D4: 12.9 | E4: 7.05 | F4: 0.4114 | G4: 6.3992 | H4: 0.233
A5: ABS INT O.B. ORIGINAL LV10 PG8 SUPER | B5: 66252 | C5: 7891010010577 | D5: 8.99 | E5: 8.25 | F5: 0.0642 | G5: 7.5809 | H5: 2.867
A6: ABS INT O.B. PROCOMFORT 8UN MEDIO | B6: 66257 | C6: 7891010245603 | D6: 8.99 | E6: 8.14 | F6: 0.08 | G6: 7.439 | H6: 2.033
A7: ABS INT O.B. PROCOMFORT 8UN SUPER | B7: 66258 | C7: 7891010245610 | D7: 8.99 | E7: 8.22 | F7: 0.0741 | G7: 7.4919 | H7: 1.067
A8: ABS INT SEMPRE LIVRE O.B. 10UN MEDIO | B8: 66253 | C8: 7891010886547 | D8: 8.99 | E8: 8.24 | F8: 0.0723 | G8: 7.5086 | H8: 1.533
A9: ABS INT SEMPRE LIVRE O.B. 16UN L+P- MEDIO | B9: 66260 | C9: 7891010245085 | D9: 19.9 | E9: 13.6 | F9: 0.2838 | G9: 12.411 | H9: 1.567
A10: ABS INT SEMPRE LIVRE O.B. 16UN L+P- SUPER | B10: 66261 | C10: 7891010245092 | D10: 19.9 | E10: 13.95 | F10: 0.2659 | G10: 12.7687 | H10: 3.033
A11: ABS INT SEMPRE LIVRE O.B. 8UN MINI | B11: 66254 | C11: 7891010245597 | D11: 8.99 | E11: 8.21 | F11: 0.0678 | G11: 7.5487 | H11: 1.233
A12: ABS INTIMUS 8UN C/ABA SECA | B12: 6999 | C12: 7896007540631 | D12: 7.15 | E12: 3.48 | F12: 0.4657 | G12: 3.1589 | H12: 5.433
A13: ABS INTIMUS 8UN EXTRA SUAVE C/ABA | B13: 7012 | C13: 7896007540617 | D13: 7.15 | E13: 3.5 | F13: 0.4641 | G13: 3.1702 | H13: 7.6
A14: ABS INTIMUS 8UN EXTRA SUAVE S/ABA | B14: 7013 | C14: 7896007540600 | D14: 7.15 | E14: 3.56 | F14: 0.4578 | G14: 3.2151 | H14: 5.433
... A3092: DOCE FONDANT SERRA MINEIRA 223G MORANGO | B3092: 67225 | C3092: 7898970476191 | D3092: 12.9 | E3092: 12.11 | F3092: 0.0557 | G3092: 10.9879 | H3092: 2.2
A3093: DOCE GOIABA HUE CREMOSO DIET 210G | B3093: 6094 | D3093: 0 | E3093: 0 | F3093: 0 | G3093: 0 | H3093: 0
A3094: DOCE GOIABADA SEGREDOS FAZENDA 270G | B3094: 67918 | C3094: 7896659100030 | D3094: 11.87 | E3094: 6.85 | F3094: 0.3838 | G3094: 6.2192 | H3094: 1.2
A3095: DOCE GOIABADA SEGREDOS FAZENDA 500G | B3095: 67927 | C3095: 7896659100146 | D3095: 27.9 | E3095: 12.68 | F3095: 0.495 | G3095: 11.5094 | H3095: 0.633
A3096: DOCE NATA SERRA MINEIRA 223G CAFE | B3096: 67226 | C3096: 7908681000025 | D3096: 12.9 | E3096: 12.11 | F3096: 0.0557 | G3096: 10.9879 | H3096: 2.067
A3097: DOGUITOS RODIZIO 65G CARNE | B3097: 11452 | C3097: 7891000623008 | D3097: 7.9 | E3097: 4.76 | F3097: 0.2892 | G3097: 3.4624 | H3097: 7.1
A3098: DOGUITOS RODIZIO 65G FRANGO | B3098: 11453 | C3098: 7891000623107 | D3098: 7.9 | E3098: 4.72 | F3098: 0.2964 | G3098: 3.4058 | H3098: 1.667
A3099: DOGUITOS RODIZIO LINGUICINHA 45G | B3099: 11455 | C3099: 7891000259078 | D3099: 7.9 | E3099: 4.78 | F3099: 0.2878 | G3099: 3.4739 | H3099: 4.2
A3100: DORAYAKI AZUKI CASTELLA 280G | B3100: 65599 | C3100: 7896175324743 | D3100: 22.9 | E3100: 17.89 | F3100: 0.1986 | G3100: 16.2348 | H3100: 0.133
A3101: DORAYAKI CREME CASTELLA 280G | B3101: 65598 | C3101: 7896175324736 | D3101: 22.9 | E3101: 17.89 | F3101: 0.1987 | G3101: 16.2322 | H3101: 0.5
A3102: DUETO KNORR 170G | B3102: 48241 | C3102: 7891150058873 | D3102: 6.99 | E3102: 5.24 | F3102: 0.2275 | G3102: 4.7529 | H3102: 6.867
A3103: ELIMINADOR ODOR DOG SANOL 2L CITRON | B3103: 12752 | C3103: 7896183301378 | D3103: 19.9 | E3103: 12.38 | F3103: 0.258 | G3103: 9.3421 | H3103: 0.367
A3104: ELIMINADOR ODOR DOG SANOL 2L HERBAL | B3104: 12753 | C3104: 7896183301040 | D3104: 19.9 | E3104: 13.38 | F3104: 0.2382 | G3104: 9.7362 | H3104: 0.233
A3105: ELIMINADOR ODOR DOG SANOL 2L TRAD | B3105: 12754 | C3105: 7896183300630 | D3105: 19.9 | E3105: 13.1 | F3105: 0.2342 | G3105: 9.8163 | H3105: 0.567
... A4948: OVO PASCOA LUISA ABRAM 170G CROC AO LEITE | B4948: 66783 | C4948: 7898972272050 | D4948: 159.9 | E4948: 148.44 | F4948: 0.0521 | G4948: 107.9933 | H4948: 0
A4949: OVO PASCOA LUISA ABRAM 170G INTENSO COM LARANJA | B4949: 66785 | D4949: 159.9 | E4949: 138.46 | F4949: 0.0975 | G4949: 100.7317 | H4949: 0
A4950: OVO PASCOA LUISA ABRAM 170G MARAC | B4950: 66784 | C4950: 7898972272067 | D4950: 189.9 | E4950: 183.37 | F4950: 0.025 | G4950: 133.4033 | H4950: 0
A4951: OVO PASCOA MENDOA 120G 50% CACAU CAST CAJU/BANAN | B4951: 69707 | C4951: 7898606181543 | D4951: 42.9 | E4951: 33.01 | F4951: 0.2091 | G4951: 29.96 | H4951: 0.333
A4952: OVO PASCOA MILKA SPOONABLE 128G OREO | B4952: 69336 | C4952: 7622201792077 | D4952: 59.99 | E4952: 40.51 | F4952: 0.2363 | G4952: 29.468 | H4952: 1.524
A4953: OVO PASCOA MILKA SPOONABLE 136G CREME AVELA | B4953: 69335 | C4953: 7622201791995 | D4953: 59.99 | E4953: 40.51 | F4953: 0.2363 | G4953: 29.468 | H4953: 1.168
A4954: OVO PASCOA MILKA SPOONABLE 136G CREME DE CACAU | B4954: 69219 | C4954: 7622201791964 | D4954: 59.99 | E4954: 40.51 | F4954: 0.2363 | G4954: 29.4681 | H4954: 1.067
A4955: OVO PASCOA MILKA SPOONABLE 136G CREME DE LEITE | B4955: 69220 | C4955: 7622201792022 | D4955: 59.99 | E4955: 40.51 | F4955: 0.2363 | G4955: 29.468 | H4955: 2.46
A4956: OVO PASCOA NESTLE ALPINO 349,5G | B4956: 26821 | C4956: 7891000390542 | D4956: 69.9 | E4956: 52.46 | F4956: 0.1816 | G4956: 38.1613 | H4956: 2.9
A4957: OVO PASCOA NESTLE CLASSIC 199G | B4957: 17668 | C4957: 7891000391358 | D4957: 52.9 | E4957: 37.47 | F4957: 0.2122 | G4957: 27.2572 | H4957: 0.767
A4958: OVO PASCOA NESTLE CRUNCH 205G | B4958: 26842 | C4958: 7891000376683 | D4958: 54.9 | E4958: 37.47 | F4958: 0.231 | G4958: 27.2572 | H4958: 0.669
A4959: OVO PASCOA NESTLE GALAK 199G | B4959: 26843 | C4959: 7891000393017 | D4959: 54.9 | E4959: 37.47 | F4959: 0.231 | G4959: 27.2572 | H4959: 0.5
...

Sheet Planilha2
A1: ANALISE DE PROMOÇÕES
A5: INFO PRODUTO | D5: PREÇO | G5: LUCRO | I5: ! | J5: MARGEM | L5: !
A6: PRODUTO | C6: CODIGO | D6: PR BASE | E6: PR PROMO | F6: PMZ | G6: LUCRO BASE | H6: LUCRO PROMO | I6: .EQL | J6: M% BASE | K6: M% PROMO | L6: SELL OUT
B8: CERVEJA HEINEKEN LN 330ML | C8: =IFERROR(VLOOKUP(B8,Planilha1!A:B,2,0),"-") -> 5961 | D8: =VLOOKUP(C8,Planilha1!B:D,3,0) -> 6.49 | E8: 4.99 | F8: =VLOOKUP(C8,Planilha1!B:E,4,0)-L8 -> 4.28 | G8: =D8-F8 -> 2.21 | H8: =IFERROR(E8-F8,"-") -> 0.71 | I8: =IFERROR(G8/H8,"-") -> 3.1126761 | J8: =IFERROR(G8/D8,"-") -> 0.34052388 | K8: =IFERROR(H8/E8,"-") -> 0.14228457 | L8: 0.7

Sheet BASE DE DADOS
B1: ANALISE ABC ESTOQUE MED NORMAL | K1: ANALISE ABC ESTOQUE MED SEM PROMO
A2: Produto | B2: Código Produto | C2: Código Acesso | D2: Preço Vda Unitário | E2: Preço Marg.Zero | F2: Lucrat. Marg % | G2: Custo Liq. Unitário | H2: Média Vda/Dia | K2: Código Produto | L2: Produto | M2: Média Vda/Dia
A3: TOTAL: 1872 linhas | D3: 67.45 | E3: 187.33 | F3: 27.14 | G3: 29.6681 | H3: 1025.318 | L3: TOTAL: 1872 linhas | M3: 641.966
A4: ABSINTO HABITUE 700ML | B4: 34430 | C4: 7898280300520 | D4: 59.9 | E4: 34.65 | F4: 38.23 | G4: 31.4598 | H4: 0.033 | K4: 34430 | L4: ABSINTO HABITUE 700ML | M4: 0.033
A5: AGUARDENTE BAGACEIRA NETO COSTA 1L | B5: 66876 | C5: 5601193300127 | D5: 289.9 | E5: 202.95 | F5: 27.22 | G5: 184.1811 | H5: 0 | K5: 66876 | L5: AGUARDENTE BAGACEIRA NETO COSTA 1L | M5: 0
A6: AGUARDENTE PIRASSUNUNGA 51 965ML | B6: 2919 | C6: 7896002100014 | D6: 16.9 | E6: 10.22 | F6: 35.97 | G6: 9.2584 | H6: 5.867 | K6: 2919 | L6: AGUARDENTE PIRASSUNUNGA 51 965ML | M6: 5.467
A7: AGUARDENTE SAO FRANCISCO 970ML | B7: 13299 | C7: 7891050001108 | D7: 34.9 | E7: 26.6 | F7: 18.85 | G7: 25.092 | H7: 1.167 | K7: 13299 | L7: AGUARDENTE SAO FRANCISCO 970ML | M7: 1.067
A8: AGUARDENTE YPIOCA 150 ANOS 700ML | B8: 33404 | C8: 7896383730107 | D8: 99.9 | E8: 73.05 | F8: 23.97 | G8: 66.71 | H8: 0.233 | K8: 33404 | L8: AGUARDENTE YPIOCA 150 ANOS 700ML | M8: 0.367
A9: AGUARDENTE YPIOCA 160 ANOS MALTE 700ML | B9: 33403 | C9: 7896383730114 | D9: 139.9 | E9: 104.17 | F9: 23.42 | G9: 94.1991 | H9: 0.033 | K9: 33403 | L9: AGUARDENTE YPIOCA 160 ANOS MALTE 700ML | M9: 0.033
A10: AGUARDENTE YPIOCA OURO 965ML | B10: 14915 | C10: 7896383700681 | D10: 34.9 | E10: 23.68 | F10: 28.82 | G10: 21.613 | H10: 0.833 | K10: 14915 | L10: AGUARDENTE YPIOCA OURO 965ML | M10: 0.767
A11: AGUARDENTE YPIOCA OURO PALHA 960ML | B11: 2916 | C11: 7896383700704 | D11: 59.9 | E11: 33.93 | F11: 36.11 | G11: 32.728 | H11: 0.167 | K11: 2916 | L11: AGUARDENTE YPIOCA OURO PALHA 960ML | M11: 0.167
A12: AGUARDENTE YPIOCA PRATA 965ML | B12: 18521 | C12: 7896383730152 | D12: 29.9 | E12: 19.73 | F12: 31.05 | G12: 17.8516 | H12: 0.667 | K12: 18521 | L12: AGUARDENTE YPIOCA PRATA 965ML | M12: 0.667
A13: APARELHO FONDUE QJ CERAMICA C/7 PECAS | B13: 59569 | C13: 7893220282072 | D13: 159.9 | E13: 111.23 | F13: 22.14 | G13: 80.9176 | H13: 0 | K13: 59569 | L13: APARELHO FONDUE QJ CERAMICA C/7 PECAS | M13: 0
A14: APERITIVO APEROL 750ML | B14: 21924 | C14: 7891136057012 | D14: 54.9 | E14: 31.28 | F14: 39.47 | G14: 28.1514 | H14: 3 | K14: 21924 | L14: APERITIVO APEROL 750ML | M14: 2.667
A15: APERITIVO ARAK HABITUE 750ML | B15: 34429 | C15: 7898280301510 | D15: 59.9 | E15: 33.54 | F15: 40.2 | G15: 30.2788 | H15: 0.067 | K15: 34429 | L15: APERITIVO ARAK HABITUE 750ML | M15: 0.067
... A388: KIT GIN TANQUERAY+WHISKY J WALK BLONDE 750ML | B388: 69612 | C388: 7893218004044 | D388: 249.9 | E388: 172.75 | F388: 28.02 | G388: 156.7679 | H388: 0.139 | K388: 69612 | L388: KIT GIN TANQUERAY+WHISKY J WALK BLONDE 750ML | M388: 0.139
A389: KIT VINHO ESPORAO RES VERTICAL 750ML | B389: 63485 | D389: 999.9 | E389: 747.22 | F389: 16.62 | G389: 491.3 | H389: 0 | K389: 63485 | L389: KIT VINHO ESPORAO RES VERTICAL 750ML | M389: 0
A390: KIT VINHO REGUENGOS TINTO 750ML C/6 | B390: 67213 | C390: 15601377001915 | D390: 149.9 | E390: 197.53 | F390: -20.89 | G390: 129.8741 | H390: 0.4 | K390: 67213 | L390: KIT VINHO REGUENGOS TINTO 750ML C/6 | M390: 0
A391: KIT WHISKY J WALK 18 ANOS 50ML | B391: 65881 | C391: 5000267171470 | D391: 49.9 | E391: 117.14 | F391: -122.29 | G391: 106.307 | H391: 0.933 | K391: 65881 | L391: KIT WHISKY J WALK 18 ANOS 50ML | M391: 0.933
A392: LICOR 750ML DOCE DE LEITE MEIA LUA | B392: 69746 | C392: 7898954956725 | D392: 54.9 | E392: 40.94 | F392: 23.08 | G392: 37.1492 | H392: 5.483 | K392: 69746 | L392: LICOR 750ML DOCE DE LEITE MEIA LUA | M392: 0.167
A393: LICOR AMARETTO DELL' ORSO 700ML | B393: 29275 | C393: 78901612 | D393: 99.9 | E393: 66.55 | F393: 30.45 | G393: 60.2394 | H393: 0.167 | K393: 29275 | L393: LICOR AMARETTO DELL' ORSO 700ML | M393: 0.167
A394: LICOR AMARULA CHOCOLATE 750ML | B394: 65941 | C394: 6001108108685 | D394: 149.9 | E394: 112.68 | F394: 22.53 | G394: 102.26 | H394: 0.033 | K394: 65941 | L394: LICOR AMARULA CHOCOLATE 750ML | M394: 0.033
A395: LICOR AMARULA COFFEE 750ML | B395: 65942 | C395: 6001108103956 | D395: 149.9 | E395: 112.68 | F395: 22.53 | G395: 102.259 | H395: 0.033 | K395: 65942 | L395: LICOR AMARULA COFFEE 750ML | M395: 0.033
A396: LICOR AMARULA CREAM 750ML | B396: 12473 | C396: 7898235980975 | D396: 149.9 | E396: 84.71 | F396: 39.72 | G396: 76.4968 | H396: 0.8 | K396: 12473 | L396: LICOR AMARULA CREAM 750ML | M396: 0.767
A397: LICOR AMARULA VANILLA 750ML | B397: 55576 | C397: 6001108093776 | D397: 149.9 | E397: 112.68 | F397: 22.53 | G397: 102.2594 | H397: 0.067 | K397: 55576 | L397: LICOR AMARULA VANILLA 750ML | M397: 0.067
A398: LICOR AMENDOA AMARGUINHA 700ML | B398: 13989 | C398: 5601358490014 | D398: 199.9 | E398: 149.58 | F398: 22.84 | G398: 135.7426 | H398: 0 | K398: 13989 | L398: LICOR AMENDOA AMARGUINHA 700ML | M398: 0
A399: LICOR BAILEYS 750ML | B399: 23564 | C399: 5011013100132 | D399: 169.9 | E399: 123.63 | F399: 23.87 | G399: 113.6232 | H399: 0.367 | K399: 23564 | L399: LICOR BAILEYS 750ML | M399: 0.233
A400: LICOR CACHACA WEBER HAUS ORG 500ML | B400: 49223 | C400: 7898013030397 | D400: 84.9 | E400: 62.28 | F400: 24.18 | G400: 56.5157 | H400: 0 | K400: 49223 | L400: LICOR CACHACA WEBER HAUS ORG 500ML | M400: 0
A401: LICOR CAFE BUCCO 500ML | B401: 60833 | C401: 7898904741319 | D401: 99.9 | E401: 79.54 | F401: 18.49 | G401: 72.1843 | H401: 0.033 | K401: 60833 | L401: LICOR CAFE BUCCO 500ML | M401: 0.033
... A1875: XAROPE MONIN 330ML PIPOCA | B1875: 66439 | C1875: 3052911593321 | D1875: 35.9 | E1875: 23.84 | F1875: 24.45 | G1875: 17.3402 | H1875: 1.033 | K1875: 66439 | L1875: XAROPE MONIN 330ML PIPOCA | M1875: 0.233

Sheet ADEGA
A1: ANALISE DE PROMOÇÕES
A5: INFO PRODUTO | D5: PREÇO | G5: LUCRO | I5: ! | J5: MARGEM | L5: ! | M5: MEDIA DE VENDA | O5: ! | P5: PROJEÇÃO VENDA | R5: PROJEÇÃO LUCRO | T5: ! | U5: PROJEÇ. QUANTIDADE
A6: PRODUTO | C6: CODIGO | D6: PR BASE | E6: PR PROMO | F6: PMZ | G6: LUCRO BASE | H6: LUCRO PROMO | I6: .EQL | J6: M% BASE | K6: M% PROMO | L6: SELL OUT | M6: M. V. BASE | N6: M. V. PROMO | O6: DIAS PROMO | P6: PROJEÇÃO V. BASE | Q6: PROJEÇÃO V. PROMO | R6: PROJEÇÃO L. BASE | S6: PROJEÇÃO L. PROMO | T6: QUANT. P.EQ | U6: QUANT. BASE | V6: QUANT. PROMO
B8: LICOR ESP DIEGO ZAMORA 43 700ML | C8: =IFERROR(VLOOKUP(B8,'BASE DE DADOS'!A:B,2,0),"-") -> 24163 | D8: =VLOOKUP(C8,'BASE DE DADOS'!B:D,3,0) -> 179.9 | E8: 149.9 | F8: =VLOOKUP(C8,'BASE DE DADOS'!B:E,4,0)-L8 -> 114.15 | G8: =D8-F8 -> 65.75 | H8: =IFERROR(E8-F8,"-") -> 35.75 | I8: =IFERROR(G8/H8,"-") -> 1.8391608 | J8: =IFERROR(G8/D8,"-") -> 0.36548082 | K8: =IFERROR(H8/E8,"-") -> 0.23849233 | M8: =VLOOKUP(C8,'BASE DE DADOS'!K:M,3,0) -> 0.433 | N8: =VLOOKUP(C8,'BASE DE DADOS'!B:H,7,0) -> 1.467 | O8: 10 | P8: =IFERROR(O8*D8*M8,"-") -> 778.967 | Q8: =IFERROR(N8*E8*O8,"-") -> 2199.033 | R8: =IFERROR(G8*U8,"-") -> 284.6975 | S8: =IFERROR(H8*V8,"-") -> 524.4525 | T8: =I8*M8*O8 -> 7.9635664 | U8: =M8*O8 -> 4.33 | V8: =N8*O8 -> 14.67
P10: VAR% (VENDA) | R10: VAR% (LUCRO) | U10: VAR% (QUANTIDADE)
P11: =Q8/P8-1 -> 1.8230118 | R11: =S8/R8-1 -> 0.84213946 | U11: =V8/U8-1 -> 2.3879908
