Workbook

Sheet Dados do BI
A1: Colar a planilha do BI - Se alterar manualmente as taxas, muda no resumo
A4: if(CODESPECIE_PROPOSAL = 'CARDEB','Débito','Credito') | B4: Credito | C4: Credito | D4: Credito | E4: Credito | F4: Credito | G4: Credito | H4: Credito | I4: Credito | J4: Credito | K4: Credito | L4: Credito | M4: Credito | N4: Credito | O4: Credito | P4: Credito | Q4: Débito | R4: Débito | S4: Débito | T4: Débito | U4: Débito | V4: Débito
A5: BANDEIRA_PROPOSAL | B5: AMERICAN EXPRESS | C5: AMERICAN EXPRESS | D5: AMERICAN EXPRESS | E5: ELO | F5: ELO | G5: ELO | H5: HIPERCARD | I5: HIPERCARD | J5: HIPERCARD | K5: MASTERCARD | L5: MASTERCARD | M5: MASTERCARD | N5: VISA | O5: VISA | P5: VISA | Q5: ELO | R5: ELO | S5: ELO | T5: VISA | U5: VISA | V5: VISA
A6: ADQUIRENTE | B6: Taxas (%) | C6: Total | D6: Taxa R$ | E6: Taxas (%) | F6: Total | G6: Taxa R$ | H6: Taxas (%) | I6: Total | J6: Taxa R$ | K6: Taxas (%) | L6: Total | M6: Taxa R$ | N6: Taxas (%) | O6: Total | P6: Taxa R$ | Q6: Taxas (%) | R6: Total | S6: Taxa R$ | T6: Taxas (%) | U6: Total | V6: Taxa R$
A7: CIELO | B7: 0.0138 | C7: 4219179.8 | D7: 58224.681 | E7: 0.0142 | F7: 11084702 | G7: 157402.76 | H7: 0.0142 | I7: 168797.58 | J7: 2396.9256 | K7: 0.0149 | L7: 1.4135075e+08 | M7: 2106126.1 | N7: 0.0151 | O7: 1.0523158e+08 | P7: 1588996.8 | Q7: 0.0073 | R7: 20255514 | S7: 147865.25 | T7: 0.0072 | U7: 72286329 | V7: 520461.57
A8: FISERV | B8: 0.0249 | C8: 4219179.8 | D8: 105057.58 | E8: 0.0115 | F8: 11084702 | G8: 127474.07 | H8: 0.0249 | I8: 168797.58 | J8: 4203.0597 | K8: 0.0115 | L8: 1.4135075e+08 | M8: 1625533.6 | N8: 0.0116 | O8: 1.0523158e+08 | P8: 1220686.3 | Q8: 0.0086 | R8: 20255514 | S8: 174197.42 | T8: 0.0086 | U8: 72286329 | V8: 621662.43
A9: GETNET | B9: 0.0199 | C9: 4219179.8 | D9: 83961.678 | E9: 0.0151 | F9: 11084702 | G9: 167378.99 | H9: 0.0111 | I9: 168797.58 | J9: 1873.6531 | K9: 0.0148 | L9: 1.4135075e+08 | M9: 2091991.1 | N9: 0.0155 | O9: 1.0523158e+08 | P9: 1631089.4 | Q9: 0.0072 | R9: 20255514 | S9: 145839.7 | T9: 0.0075 | U9: 72286329 | V9: 542147.47
A10: REDE | B10: 0.022 | C10: 4219179.8 | D10: 92821.956 | E10: 0.0199 | F10: 11084702 | G10: 220585.56 | H10: 0.0145 | I10: 168797.58 | J10: 2447.5649 | K10: 0.0129 | L10: 1.4135075e+08 | M10: 1823424.6 | N10: 0.0129 | O10: 1.0523158e+08 | P10: 1357487.3 | Q10: 0.0099 | R10: 20255514 | S10: 200529.58 | T10: 0.0067 | U10: 72286329 | V10: 484318.41
A11: SAFRAPAY | B11: 0.0188 | C11: 4219179.8 | D11: 79320.58 | E11: 0.0135 | F11: 11084702 | G11: 149643.47 | H11: 0.0139 | I11: 168797.58 | J11: 2346.2864 | K11: 0.0167 | L11: 1.4135075e+08 | M11: 2360557.5 | N11: 0.0156 | O11: 1.0523158e+08 | P11: 1641612.6 | Q11: 0.0063 | R11: 20255514 | S11: 127609.74 | T11: 0.0072 | U11: 72286329 | V11: 520461.57
A12: STONE | B12: 0.0224 | C12: 4219179.8 | D12: 94509.628 | E12: 0.0224 | F12: 11084702 | G12: 248297.32 | H12: 0.0224 | I12: 168797.58 | J12: 3781.0658 | K12: 0.0174 | L12: 1.4135075e+08 | M12: 2459503 | N12: 0.0174 | O12: 1.0523158e+08 | P12: 1831029.4 | Q12: 0.0079 | R12: 20255514 | S12: 160018.56 | T12: 0.0072 | U12: 72286329 | V12: 520461.57
A13: SUMUP | B13: 0.043 | C13: 4219179.8 | D13: 181424.73 | E13: 0.043 | F13: 11084702 | G13: 476642.17 | H13: 0.043 | I13: 168797.58 | J13: 7258.2959 | K13: 0.043 | L13: 1.4135075e+08 | M13: 6078082.2 | N13: 0.009 | O13: 1.0523158e+08 | P13: 947084.19 | Q13: 0.0255 | R13: 20255514 | S13: 516515.6 | T13: 0.009 | U13: 72286329 | V13: 650576.96

Sheet Resumo
A1: Proposta Inicial
B2: Credito | C2: Credito | D2: Credito | E2: Credito | F2: Credito | G2: Credito | H2: Credito | I2: Credito | J2: Credito | K2: Credito | L2: Débito | M2: Débito | N2: Débito | O2: Débito
A3: BANDEIRA_PROPOSAL | B3: AMERICAN EXPRESS | C3: AMERICAN EXPRESS | D3: ELO | E3: ELO | F3: HIPERCARD | G3: HIPERCARD | H3: MASTERCARD | I3: MASTERCARD | J3: VISA | K3: VISA | L3: ELO | M3: ELO | N3: VISA | O3: VISA | Q3: TOTAL
A4: Total de vendas | B4: ='Dados do BI'!C7 -> 4219179.8 | D4: ='Dados do BI'!F7 -> 11084702 | F4: ='Dados do BI'!I7 -> 168797.58 | H4: ='Dados do BI'!L7 -> 1.4135075e+08 | J4: ='Dados do BI'!O7 -> 1.0523158e+08 | L4: ='Dados do BI'!R7 -> 20255514 | N4: ='Dados do BI'!U7 -> 72286329 | Q4: =SUM(B4:O4) -> 3.5459685e+08
A6: ADQUIRENTE | B6: Taxas (%) | C6: Taxa R | D6: Taxas (%) | E6: Taxa R | F6: Taxas (%) | G6: Taxa R | H6: Taxas (%) | I6: Taxa R | J6: Taxas (%) | K6: Taxa R | L6: Taxas (%) | M6: Taxa R | N6: Taxas (%) | O6: Taxa R
A7: ='Dados do BI'!A7 -> CIELO | B7: ='Dados do BI'!B7 -> 0.0138 | C7: =B4*B7 -> 58224.681 | D7: ='Dados do BI'!E7 -> 0.0142 | E7: =D4*D7 -> 157402.76 | F7: ='Dados do BI'!H7 -> 0.0142 | G7: =F4*F7 -> 2396.9256 | H7: ='Dados do BI'!K7 -> 0.0149 | I7: =H4*H7 -> 2106126.1 | J7: ='Dados do BI'!N7 -> 0.0151 | K7: =J4*J7 -> 1588996.8 | L7: ='Dados do BI'!Q7 -> 0.0073 | M7: =L4*L7 -> 147865.25 | N7: ='Dados do BI'!T7 -> 0.0072 | O7: =N4*N7 -> 520461.57
A8: ='Dados do BI'!A8 -> FISERV | B8: ='Dados do BI'!B8 -> 0.0249 | C8: =B4*B8 -> 105057.58 | D8: ='Dados do BI'!E8 -> 0.0115 | E8: =D4*D8 -> 127474.07 | F8: ='Dados do BI'!H8 -> 0.0249 | G8: =F4*F8 -> 4203.0597 | H8: ='Dados do BI'!K8 -> 0.0115 | I8: =H4*H8 -> 1625533.6 | J8: ='Dados do BI'!N8 -> 0.0116 | K8: =J4*J8 -> 1220686.3 | L8: ='Dados do BI'!Q8 -> 0.0086 | M8: =L4*L8 -> 174197.42 | N8: ='Dados do BI'!T8 -> 0.0086 | O8: =N4*N8 -> 621662.43
A9: ='Dados do BI'!A9 -> GETNET | B9: ='Dados do BI'!B9 -> 0.0199 | C9: =B4*B9 -> 83961.678 | D9: ='Dados do BI'!E9 -> 0.0151 | E9: =D4*D9 -> 167378.99 | F9: ='Dados do BI'!H9 -> 0.0111 | G9: =F4*F9 -> 1873.6531 | H9: ='Dados do BI'!K9 -> 0.0148 | I9: =H4*H9 -> 2091991.1 | J9: ='Dados do BI'!N9 -> 0.0155 | K9: =J4*J9 -> 1631089.4 | L9: ='Dados do BI'!Q9 -> 0.0072 | M9: =L4*L9 -> 145839.7 | N9: ='Dados do BI'!T9 -> 0.0075 | O9: =N4*N9 -> 542147.47
A10: ='Dados do BI'!A10 -> REDE | B10: ='Dados do BI'!B10 -> 0.022 | C10: =B4*B10 -> 92821.956 | D10: ='Dados do BI'!E10 -> 0.0199 | E10: =D4*D10 -> 220585.56 | F10: ='Dados do BI'!H10 -> 0.0145 | G10: =F4*F10 -> 2447.5649 | H10: ='Dados do BI'!K10 -> 0.0129 | I10: =H4*H10 -> 1823424.6 | J10: ='Dados do BI'!N10 -> 0.0129 | K10: =J4*J10 -> 1357487.3 | L10: ='Dados do BI'!Q10 -> 0.0099 | M10: =L4*L10 -> 200529.58 | N10: ='Dados do BI'!T10 -> 0.0067 | O10: =N4*N10 -> 484318.41
A11: ='Dados do BI'!A11 -> SAFRAPAY | B11: ='Dados do BI'!B11 -> 0.0188 | C11: =B4*B11 -> 79320.58 | D11: ='Dados do BI'!E11 -> 0.0135 | E11: =D4*D11 -> 149643.47 | F11: ='Dados do BI'!H11 -> 0.0139 | G11: =F4*F11 -> 2346.2864 | H11: ='Dados do BI'!K11 -> 0.0167 | I11: =H4*H11 -> 2360557.5 | J11: ='Dados do BI'!N11 -> 0.0156 | K11: =J4*J11 -> 1641612.6 | L11: ='Dados do BI'!Q11 -> 0.0063 | M11: =L4*L11 -> 127609.74 | N11: ='Dados do BI'!T11 -> 0.0072 | O11: =N4*N11 -> 520461.57
A12: ='Dados do BI'!A12 -> STONE | B12: ='Dados do BI'!B12 -> 0.0224 | C12: =B4*B12 -> 94509.628 | D12: ='Dados do BI'!E12 -> 0.0224 | E12: =D4*D12 -> 248297.32 | F12: ='Dados do BI'!H12 -> 0.0224 | G12: =F4*F12 -> 3781.0658 | H12: ='Dados do BI'!K12 -> 0.0174 | I12: =H4*H12 -> 2459503 | J12: ='Dados do BI'!N12 -> 0.0174 | K12: =J4*J12 -> 1831029.4 | L12: ='Dados do BI'!Q12 -> 0.0079 | M12: =L4*L12 -> 160018.56 | N12: ='Dados do BI'!T12 -> 0.0072 | O12: =N4*N12 -> 520461.57
A13: ='Dados do BI'!A13 -> SUMUP | B13: ='Dados do BI'!B13 -> 0.043 | C13: =B4*B13 -> 181424.73 | D13: ='Dados do BI'!E13 -> 0.043 | E13: =D4*D13 -> 476642.17 | F13: ='Dados do BI'!H13 -> 0.043 | G13: =F4*F13 -> 7258.2959 | H13: ='Dados do BI'!K13 -> 0.043 | I13: =H4*H13 -> 6078082.2 | J13: ='Dados do BI'!N13 -> 0.009 | K13: =J4*J13 -> 947084.19 | L13: ='Dados do BI'!Q13 -> 0.0255 | M13: =L4*L13 -> 516515.6 | N13: ='Dados do BI'!T13 -> 0.009 | O13: =N4*N13 -> 650576.96
A15: 1º Melhor cenário | B15: =SMALL(B7:B13,1) -> 0.0138 | C15: =SMALL(C7:C13,1) -> 58224.681 | D15: =SMALL(D7:D13,1) -> 0.0115 | E15: =SMALL(E7:E13,1) -> 127474.07 | F15: =SMALL(F7:F13,1) -> 0.0111 | G15: =SMALL(G7:G13,1) -> 1873.6531 | H15: =SMALL(H7:H13,1) -> 0.0115 | I15: =SMALL(I7:I13,1) -> 1625533.6 | ... O15: =SMALL(O7:O13,1) -> 484318.41
C16: =IF(C15=C7,A7,IF(C15=C8,A8,IF(C15=C9,A9,IF(C15=C10,A10,IF(C15=C11,A11,IF(C15=C12,A12,IF(C15=C13,A13,"Verificar"))))))) -> CIELO | E16: =IF(E15=E7,A7,IF(E15=E8,A8,IF(E15=E9,A9,IF(E15=E10,A10,IF(E15=E11,A11,IF(E15=E12,A12,IF(E15=E13,A13,"Verificar"))))))) -> FISERV | G16: =IF(G15=G7,A7,IF(G15=G8,A8,IF(G15=G9,A9,IF(G15=G10,A10,IF(G15=G11,A11,IF(G15=G12,A12,IF(G15=G13,A13,"Verificar"))))))) -> GETNET | I16: =IF(I15=I7,A7,IF(I15=I8,A8,IF(I15=I9,A9,IF(I15=I10,A10,IF(I15=I11,A11,IF(I15=I12,A12,IF(I15=I13,A13,"Verificar"))))))) -> FISERV | K16: =IF(K15=K7,A7,IF(K15=K8,A8,IF(K15=K9,A9,IF(K15=K10,A10,IF(K15=K11,A11,IF(K15=K12,A12,IF(K15=K13,A13,"Verificar"))))))) -> SUMUP | M16: =IF(M15=M7,A7,IF(M15=M8,A8,IF(M15=M9,A9,IF(M15=M10,A10,IF(M15=M11,A11,IF(M15=M12,A12,IF(M15=M13,A13,"Verificar"))))))) -> SAFRAPAY | O16: =IF(O15=O7,A7,IF(O15=O8,A8,IF(O15=O9,A9,IF(O15=O10,A10,IF(O15=O11,A11,IF(O15=O12,A12,IF(O15=O13,A13,"Verificar"))))))) -> REDE
A17: 2º melhor cenário | B17: =SMALL(B7:B13,2) -> 0.0188 | C17: =SMALL(C7:C13,2) -> 79320.58 | D17: =SMALL(D7:D13,2) -> 0.0135 | E17: =SMALL(E7:E13,2) -> 149643.47 | F17: =SMALL(F7:F13,2) -> 0.0139 | G17: =SMALL(G7:G13,2) -> 2346.2864 | H17: =SMALL(H7:H13,2) -> 0.0129 | I17: =SMALL(I7:I13,2) -> 1823424.6 | ... O17: =SMALL(O7:O13,2) -> 520461.57
C18: =IF(C17=C7,A7,IF(C17=C8,A8,IF(C17=C9,A9,IF(C17=C10,A10,IF(C17=C11,A11,IF(C17=C12,A12,IF(C17=C13,A13,"Verificar"))))))) -> SAFRAPAY | E18: =IF(E17=E7,A7,IF(E17=E8,A8,IF(E17=E9,A9,IF(E17=E10,A10,IF(E17=E11,A11,IF(E17=E12,A12,IF(E17=E13,A13,"Verificar"))))))) -> SAFRAPAY | G18: =IF(G17=G7,A7,IF(G17=G8,A8,IF(G17=G9,A9,IF(G17=G10,A10,IF(G17=G11,A11,IF(G17=G12,A12,IF(G17=G13,A13,"Verificar"))))))) -> SAFRAPAY | I18: =IF(I17=I7,A7,IF(I17=I8,A8,IF(I17=I9,A9,IF(I17=I10,A10,IF(I17=I11,A11,IF(I17=I12,A12,IF(I17=I13,A13,"Verificar"))))))) -> REDE | K18: =IF(K17=K7,A7,IF(K17=K8,A8,IF(K17=K9,A9,IF(K17=K10,A10,IF(K17=K11,A11,IF(K17=K12,A12,IF(K17=K13,A13,"Verificar"))))))) -> FISERV | M18: =IF(M17=M7,A7,IF(M17=M8,A8,IF(M17=M9,A9,IF(M17=M10,A10,IF(M17=M11,A11,IF(M17=M12,A12,IF(M17=M13,A13,"Verificar"))))))) -> GETNET | O18: =IF(O17=O7,A7,IF(O17=O8,A8,IF(O17=O9,A9,IF(O17=O10,A10,IF(O17=O11,A11,IF(O17=O12,A12,IF(O17=O13,A13,"Verificar"))))))) -> CIELO
A19: 3º melhor cenário | B19: =SMALL(B7:B13,3) -> 0.0199 | C19: =SMALL(C7:C13,3) -> 83961.678 | D19: =SMALL(D7:D13,3) -> 0.0142 | E19: =SMALL(E7:E13,3) -> 157402.76 | F19: =SMALL(F7:F13,3) -> 0.0142 | G19: =SMALL(G7:G13,3) -> 2396.9256 | H19: =SMALL(H7:H13,3) -> 0.0148 | I19: =SMALL(I7:I13,3) -> 2091991.1 | ... O19: =SMALL(O7:O13,3) -> 520461.57
C20: =IF(C19=C7,A7,IF(C19=C8,A8,IF(C19=C9,A9,IF(C19=C10,A10,IF(C19=C11,A11,IF(C19=C12,A12,IF(C19=C13,A13,"Verificar"))))))) -> GETNET | E20: =IF(E19=E7,A7,IF(E19=E8,A8,IF(E19=E9,A9,IF(E19=E10,A10,IF(E19=E11,A11,IF(E19=E12,A12,IF(E19=E13,A13,"Verificar"))))))) -> CIELO | G20: =IF(G19=G7,A7,IF(G19=G8,A8,IF(G19=G9,A9,IF(G19=G10,A10,IF(G19=G11,A11,IF(G19=G12,A12,IF(G19=G13,A13,"Verificar"))))))) -> CIELO | I20: =IF(I19=I7,A7,IF(I19=I8,A8,IF(I19=I9,A9,IF(I19=I10,A10,IF(I19=I11,A11,IF(I19=I12,A12,IF(I19=I13,A13,"Verificar"))))))) -> GETNET | K20: =IF(K19=K7,A7,IF(K19=K8,A8,IF(K19=K9,A9,IF(K19=K10,A10,IF(K19=K11,A11,IF(K19=K12,A12,IF(K19=K13,A13,"Verificar"))))))) -> REDE | M20: =IF(M19=M7,A7,IF(M19=M8,A8,IF(M19=M9,A9,IF(M19=M10,A10,IF(M19=M11,A11,IF(M19=M12,A12,IF(M19=M13,A13,"Verificar"))))))) -> CIELO | O20: =IF(O19=O7,A7,IF(O19=O8,A8,IF(O19=O9,A9,IF(O19=O10,A10,IF(O19=O11,A11,IF(O19=O12,A12,IF(O19=O13,A13,"Verificar"))))))) -> CIELO
A22: Cotação 1
B23: Credito | C23: Credito | D23: Credito | E23: Credito | F23: Credito | G23: Credito | H23: Credito | I23: Credito | J23: Credito | K23: Credito | L23: Débito | M23: Débito | N23: Débito | O23: Débito
A24: BANDEIRA_PROPOSAL | B24: AMERICAN EXPRESS | C24: AMERICAN EXPRESS | D24: ELO | E24: ELO | F24: HIPERCARD | G24: HIPERCARD | H24: MASTERCARD | I24: MASTERCARD | J24: VISA | K24: VISA | L24: ELO | M24: ELO | N24: VISA | O24: VISA
A25: Total de vendas | B25: =B4 -> 4219179.8 | D25: =D4 -> 11084702 | F25: =F4 -> 168797.58 | H25: =H4 -> 1.4135075e+08 | J25: =J4 -> 1.0523158e+08 | L25: =L4 -> 20255514 | N25: =N4 -> 72286329
A27: ADQUIRENTE | B27: Taxas (%) | C27: Taxa R | D27: Taxas (%) | E27: Taxa R | F27: Taxas (%) | G27: Taxa R | H27: Taxas (%) | I27: Taxa R | J27: Taxas (%) | K27: Taxa R | L27: Taxas (%) | M27: Taxa R | N27: Taxas (%) | O27: Taxa R
A28: =A7 -> CIELO | C28: =B25*B28 -> 0 | E28: =D25*D28 -> 0 | G28: =F25*F28 -> 0 | I28: =H25*H28 -> 0 | K28: =J25*J28 -> 0 | M28: =L25*L28 -> 0 | O28: =N25*N28 -> 0
A29: =A8 -> FISERV | C29: =B25*B29 -> 0 | E29: =D25*D29 -> 0 | G29: =F25*F29 -> 0 | I29: =H25*H29 -> 0 | K29: =J25*J29 -> 0 | M29: =L25*L29 -> 0 | O29: =N25*N29 -> 0
A30: =A9 -> GETNET | C30: =B25*B30 -> 0 | E30: =D25*D30 -> 0 | G30: =F25*F30 -> 0 | I30: =H25*H30 -> 0 | K30: =J25*J30 -> 0 | M30: =L25*L30 -> 0 | O30: =N25*N30 -> 0
A31: =A10 -> REDE | C31: =B25*B31 -> 0 | E31: =D25*D31 -> 0 | G31: =F25*F31 -> 0 | I31: =H25*H31 -> 0 | K31: =J25*J31 -> 0 | M31: =L25*L31 -> 0 | O31: =N25*N31 -> 0
A32: =A11 -> SAFRAPAY | C32: =B25*B32 -> 0 | E32: =D25*D32 -> 0 | G32: =F25*F32 -> 0 | I32: =H25*H32 -> 0 | K32: =J25*J32 -> 0 | M32: =L25*L32 -> 0 | O32: =N25*N32 -> 0
A33: =A12 -> STONE | C33: =B25*B33 -> 0 | E33: =D25*D33 -> 0 | G33: =F25*F33 -> 0 | I33: =H25*H33 -> 0 | K33: =J25*J33 -> 0 | M33: =L25*L33 -> 0 | O33: =N25*N33 -> 0
A34: =A13 -> SUMUP | C34: =B25*B34 -> 0 | E34: =D25*D34 -> 0 | G34: =F25*F34 -> 0 | I34: =H25*H34 -> 0 | K34: =J25*J34 -> 0 | M34: =L25*L34 -> 0 | O34: =N25*N34 -> 0
A36: 1º Melhor cenário | B36: =SMALL(B28:B34,1) -> #NUM! | C36: =SMALL(C28:C34,1) -> 0 | D36: =SMALL(D28:D34,1) -> #NUM! | E36: =SMALL(E28:E34,1) -> 0 | F36: =SMALL(F28:F34,1) -> #NUM! | G36: =SMALL(G28:G34,1) -> 0 | H36: =SMALL(H28:H34,1) -> #NUM! | I36: =SMALL(I28:I34,1) -> 0 | ... O36: =SMALL(O28:O34,1) -> 0
C37: =IF(C36=C28,A28,IF(C36=C29,A29,IF(C36=C30,A30,IF(C36=C31,A31,IF(C36=C32,A32,IF(C36=C33,A33,IF(C36=C34,A34,"Verificar"))))))) -> CIELO | E37: =IF(E36=E28,A28,IF(E36=E29,A29,IF(E36=E30,A30,IF(E36=E31,A31,IF(E36=E32,A32,IF(E36=E33,A33,IF(E36=E34,A34,"Verificar"))))))) -> CIELO | G37: =IF(G36=G28,A28,IF(G36=G29,A29,IF(G36=G30,A30,IF(G36=G31,A31,IF(G36=G32,A32,IF(G36=G33,A33,IF(G36=G34,A34,"Verificar"))))))) -> CIELO | I37: =IF(I36=I28,A28,IF(I36=I29,A29,IF(I36=I30,A30,IF(I36=I31,A31,IF(I36=I32,A32,IF(I36=I33,A33,IF(I36=I34,A34,"Verificar"))))))) -> CIELO | K37: =IF(K36=K28,A28,IF(K36=K29,A29,IF(K36=K30,A30,IF(K36=K31,A31,IF(K36=K32,A32,IF(K36=K33,A33,IF(K36=K34,A34,"Verificar"))))))) -> CIELO | M37: =IF(M36=M28,A28,IF(M36=M29,A29,IF(M36=M30,A30,IF(M36=M31,A31,IF(M36=M32,A32,IF(M36=M33,A33,IF(M36=M34,A34,"Verificar"))))))) -> CIELO | O37: =IF(O36=O28,A28,IF(O36=O29,A29,IF(O36=O30,A30,IF(O36=O31,A31,IF(O36=O32,A32,IF(O36=O33,A33,IF(O36=O34,A34,"Verificar"))))))) -> CIELO
A38: 2º melhor cenário | B38: =SMALL(B28:B34,2) -> #NUM! | C38: =SMALL(C28:C34,2) -> 0 | D38: =SMALL(D28:D34,2) -> #NUM! | E38: =SMALL(E28:E34,2) -> 0 | F38: =SMALL(F28:F34,2) -> #NUM! | G38: =SMALL(G28:G34,2) -> 0 | H38: =SMALL(H28:H34,2) -> #NUM! | I38: =SMALL(I28:I34,2) -> 0 | ... O38: =SMALL(O28:O34,2) -> 0
C39: =IF(C38=C28,A28,IF(C38=C29,A29,IF(C38=C30,A30,IF(C38=C31,A31,IF(C38=C32,A32,IF(C38=C33,A33,IF(C38=C34,A34,"Verificar"))))))) -> CIELO | E39: =IF(E38=E28,A28,IF(E38=E29,A29,IF(E38=E30,A30,IF(E38=E31,A31,IF(E38=E32,A32,IF(E38=E33,A33,IF(E38=E34,A34,"Verificar"))))))) -> CIELO | G39: =IF(G38=G28,A28,IF(G38=G29,A29,IF(G38=G30,A30,IF(G38=G31,A31,IF(G38=G32,A32,IF(G38=G33,A33,IF(G38=G34,A34,"Verificar"))))))) -> CIELO | I39: =IF(I38=I28,A28,IF(I38=I29,A29,IF(I38=I30,A30,IF(I38=I31,A31,IF(I38=I32,A32,IF(I38=I33,A33,IF(I38=I34,A34,"Verificar"))))))) -> CIELO | K39: =IF(K38=K28,A28,IF(K38=K29,A29,IF(K38=K30,A30,IF(K38=K31,A31,IF(K38=K32,A32,IF(K38=K33,A33,IF(K38=K34,A34,"Verificar"))))))) -> CIELO | M39: =IF(M38=M28,A28,IF(M38=M29,A29,IF(M38=M30,A30,IF(M38=M31,A31,IF(M38=M32,A32,IF(M38=M33,A33,IF(M38=M34,A34,"Verificar"))))))) -> CIELO | O39: =IF(O38=O28,A28,IF(O38=O29,A29,IF(O38=O30,A30,IF(O38=O31,A31,IF(O38=O32,A32,IF(O38=O33,A33,IF(O38=O34,A34,"Verificar"))))))) -> CIELO
A40: 3º melhor cenário | B40: =SMALL(B28:B34,3) -> #NUM! | C40: =SMALL(C28:C34,3) -> 0 | D40: =SMALL(D28:D34,3) -> #NUM! | E40: =SMALL(E28:E34,3) -> 0 | F40: =SMALL(F28:F34,3) -> #NUM! | G40: =SMALL(G28:G34,3) -> 0 | H40: =SMALL(H28:H34,3) -> #NUM! | I40: =SMALL(I28:I34,3) -> 0 | ... O40: =SMALL(O28:O34,3) -> 0
C41: =IF(C40=C28,A28,IF(C40=C29,A29,IF(C40=C30,A30,IF(C40=C31,A31,IF(C40=C32,A32,IF(C40=C33,A33,IF(C40=C34,A34,"Verificar"))))))) -> CIELO | E41: =IF(E40=E28,A28,IF(E40=E29,A29,IF(E40=E30,A30,IF(E40=E31,A31,IF(E40=E32,A32,IF(E40=E33,A33,IF(E40=E34,A34,"Verificar"))))))) -> CIELO | G41: =IF(G40=G28,A28,IF(G40=G29,A29,IF(G40=G30,A30,IF(G40=G31,A31,IF(G40=G32,A32,IF(G40=G33,A33,IF(G40=G34,A34,"Verificar"))))))) -> CIELO | I41: =IF(I40=I28,A28,IF(I40=I29,A29,IF(I40=I30,A30,IF(I40=I31,A31,IF(I40=I32,A32,IF(I40=I33,A33,IF(I40=I34,A34,"Verificar"))))))) -> CIELO | K41: =IF(K40=K28,A28,IF(K40=K29,A29,IF(K40=K30,A30,IF(K40=K31,A31,IF(K40=K32,A32,IF(K40=K33,A33,IF(K40=K34,A34,"Verificar"))))))) -> CIELO | M41: =IF(M40=M28,A28,IF(M40=M29,A29,IF(M40=M30,A30,IF(M40=M31,A31,IF(M40=M32,A32,IF(M40=M33,A33,IF(M40=M34,A34,"Verificar"))))))) -> CIELO | O41: =IF(O40=O28,A28,IF(O40=O29,A29,IF(O40=O30,A30,IF(O40=O31,A31,IF(O40=O32,A32,IF(O40=O33,A33,IF(O40=O34,A34,"Verificar"))))))) -> CIELO
A43: Cotação 2
B44: Credito | C44: Credito | D44: Credito | E44: Credito | F44: Credito | G44: Credito | H44: Credito | I44: Credito | J44: Credito | K44: Credito | L44: Débito | M44: Débito | N44: Débito | O44: Débito
A45: BANDEIRA_PROPOSAL | B45: AMERICAN EXPRESS | C45: AMERICAN EXPRESS | D45: ELO | E45: ELO | F45: HIPERCARD | G45: HIPERCARD | H45: MASTERCARD | I45: MASTERCARD | J45: VISA | K45: VISA | L45: ELO | M45: ELO | N45: VISA | O45: VISA
A46: Total de vendas | B46: =B25 -> 4219179.8 | D46: =D25 -> 11084702 | F46: =F25 -> 168797.58 | H46: =H25 -> 1.4135075e+08 | J46: =J25 -> 1.0523158e+08 | L46: =L25 -> 20255514 | N46: =N25 -> 72286329
...
